2023-05-06 21:50:43.189 ERROR (MainThread) [homeassistant] Error doing job: _GatheringFuture exception was never retrieved
asyncio.exceptions.CancelledError

During handling of the above exception, another exception occurred:

asyncio.exceptions.CancelledError
